2024-05-16 17:52:57,702 INFO werkzeug [31m[1mWARNING: This is a development server. Do not use it in a production deployment. Use a production WSGI server instead.[0m
 * Running on all addresses (0.0.0.0)
 * Running on http://127.0.0.1:5000
 * Running on http://192.168.0.176:5000
2024-05-16 17:52:57,702 INFO werkzeug [33mPress CTRL+C to quit[0m
2024-05-16 17:53:20,061 INFO werkzeug [31m[1mWARNING: This is a development server. Do not use it in a production deployment. Use a production WSGI server instead.[0m
 * Running on all addresses (0.0.0.0)
 * Running on http://127.0.0.1:5000
 * Running on http://192.168.0.176:5000
2024-05-16 17:53:20,063 INFO werkzeug [33mPress CTRL+C to quit[0m
2024-05-16 17:55:22,956 ERROR main Exception on /comment [POST]
Traceback (most recent call last):
  File "C:\Users\huang\LLMChat\venv\lib\site-packages\flask\app.py", line 1473, in wsgi_app
    response = self.full_dispatch_request()
  File "C:\Users\huang\LLMChat\venv\lib\site-packages\flask\app.py", line 883, in full_dispatch_request
    return self.finalize_request(rv)
  File "C:\Users\huang\LLMChat\venv\lib\site-packages\flask\app.py", line 902, in finalize_request
    response = self.make_response(rv)
  File "C:\Users\huang\LLMChat\venv\lib\site-packages\flask\app.py", line 1174, in make_response
    raise TypeError(
TypeError: The view function for 'comment' did not return a valid response. The function either returned None or ended without a return statement.
2024-05-16 17:55:22,958 INFO werkzeug 127.0.0.1 - - [16/May/2024 17:55:22] "[35m[1mPOST /comment HTTP/1.1[0m" 500 -
2024-05-16 17:56:10,875 INFO werkzeug [31m[1mWARNING: This is a development server. Do not use it in a production deployment. Use a production WSGI server instead.[0m
 * Running on all addresses (0.0.0.0)
 * Running on http://127.0.0.1:5000
 * Running on http://192.168.0.176:5000
2024-05-16 17:56:10,875 INFO werkzeug [33mPress CTRL+C to quit[0m
2024-05-16 17:56:14,884 ERROR main Exception on /comment [POST]
Traceback (most recent call last):
  File "C:\Users\huang\LLMChat\venv\lib\site-packages\flask\app.py", line 1473, in wsgi_app
    response = self.full_dispatch_request()
  File "C:\Users\huang\LLMChat\venv\lib\site-packages\flask\app.py", line 883, in full_dispatch_request
    return self.finalize_request(rv)
  File "C:\Users\huang\LLMChat\venv\lib\site-packages\flask\app.py", line 902, in finalize_request
    response = self.make_response(rv)
  File "C:\Users\huang\LLMChat\venv\lib\site-packages\flask\app.py", line 1174, in make_response
    raise TypeError(
TypeError: The view function for 'comment' did not return a valid response. The function either returned None or ended without a return statement.
2024-05-16 17:56:14,885 INFO werkzeug 127.0.0.1 - - [16/May/2024 17:56:14] "[35m[1mPOST /comment HTTP/1.1[0m" 500 -
2024-05-16 19:37:43,425 INFO werkzeug [31m[1mWARNING: This is a development server. Do not use it in a production deployment. Use a production WSGI server instead.[0m
 * Running on all addresses (0.0.0.0)
 * Running on http://127.0.0.1:5000
 * Running on http://192.168.0.176:5000
2024-05-16 19:37:43,426 INFO werkzeug [33mPress CTRL+C to quit[0m
2024-05-16 19:37:48,006 ERROR main Exception on /comment [POST]
Traceback (most recent call last):
  File "C:\Users\huang\LLMChat\main.py", line 33, in comment
    system_prompt = prompts.comment.system_prompt.format(criteria=inputs['all_criteria'],
  File "C:\Users\huang\LLMChat\venv\lib\site-packages\langchain_core\prompts\prompt.py", line 127, in format
    return DEFAULT_FORMATTER_MAPPING[self.template_format](self.template, **kwargs)
  File "C:\Users\huang\AppData\Local\Programs\Python\Python39\lib\string.py", line 161, in format
    return self.vformat(format_string, args, kwargs)
  File "C:\Users\huang\LLMChat\venv\lib\site-packages\langchain_core\utils\formatting.py", line 18, in vformat
    return super().vformat(format_string, args, kwargs)
  File "C:\Users\huang\AppData\Local\Programs\Python\Python39\lib\string.py", line 165, in vformat
    result, _ = self._vformat(format_string, args, kwargs, used_args, 2)
  File "C:\Users\huang\AppData\Local\Programs\Python\Python39\lib\string.py", line 205, in _vformat
    obj, arg_used = self.get_field(field_name, args, kwargs)
  File "C:\Users\huang\AppData\Local\Programs\Python\Python39\lib\string.py", line 270, in get_field
    obj = self.get_value(first, args, kwargs)
  File "C:\Users\huang\AppData\Local\Programs\Python\Python39\lib\string.py", line 227, in get_value
    return kwargs[key]
KeyError: 'assignment context'

During handling of the above exception, another exception occurred:

Traceback (most recent call last):
  File "C:\Users\huang\LLMChat\venv\lib\site-packages\flask\app.py", line 1473, in wsgi_app
    response = self.full_dispatch_request()
  File "C:\Users\huang\LLMChat\venv\lib\site-packages\flask\app.py", line 882, in full_dispatch_request
    rv = self.handle_user_exception(e)
  File "C:\Users\huang\LLMChat\venv\lib\site-packages\flask\app.py", line 880, in full_dispatch_request
    rv = self.dispatch_request()
  File "C:\Users\huang\LLMChat\venv\lib\site-packages\flask\app.py", line 865, in dispatch_request
    return self.ensure_sync(self.view_functions[rule.endpoint])(**view_args)  # type: ignore[no-any-return]
  File "C:\Users\huang\LLMChat\main.py", line 42, in comment
    logging_config.error_logger(Exception, e)
  File "C:\Users\huang\LLMChat\logging_config.py", line 16, in error_logger
    logger.error(f'Error occurred: {e}')
AttributeError: type object 'Exception' has no attribute 'error'
2024-05-16 19:37:48,009 INFO werkzeug 127.0.0.1 - - [16/May/2024 19:37:48] "[35m[1mPOST /comment HTTP/1.1[0m" 500 -
2024-05-16 19:38:23,890 INFO werkzeug [31m[1mWARNING: This is a development server. Do not use it in a production deployment. Use a production WSGI server instead.[0m
 * Running on all addresses (0.0.0.0)
 * Running on http://127.0.0.1:5000
 * Running on http://192.168.0.176:5000
2024-05-16 19:38:23,890 INFO werkzeug [33mPress CTRL+C to quit[0m
2024-05-16 19:38:28,043 ERROR main Exception on /comment [POST]
Traceback (most recent call last):
  File "C:\Users\huang\LLMChat\main.py", line 32, in comment
    system_prompt = prompts.comment.system_prompt.format(criteria=inputs['all_criteria'],
  File "C:\Users\huang\LLMChat\venv\lib\site-packages\langchain_core\prompts\prompt.py", line 127, in format
    return DEFAULT_FORMATTER_MAPPING[self.template_format](self.template, **kwargs)
  File "C:\Users\huang\AppData\Local\Programs\Python\Python39\lib\string.py", line 161, in format
    return self.vformat(format_string, args, kwargs)
  File "C:\Users\huang\LLMChat\venv\lib\site-packages\langchain_core\utils\formatting.py", line 18, in vformat
    return super().vformat(format_string, args, kwargs)
  File "C:\Users\huang\AppData\Local\Programs\Python\Python39\lib\string.py", line 165, in vformat
    result, _ = self._vformat(format_string, args, kwargs, used_args, 2)
  File "C:\Users\huang\AppData\Local\Programs\Python\Python39\lib\string.py", line 205, in _vformat
    obj, arg_used = self.get_field(field_name, args, kwargs)
  File "C:\Users\huang\AppData\Local\Programs\Python\Python39\lib\string.py", line 270, in get_field
    obj = self.get_value(first, args, kwargs)
  File "C:\Users\huang\AppData\Local\Programs\Python\Python39\lib\string.py", line 227, in get_value
    return kwargs[key]
KeyError: 'assignment context'

During handling of the above exception, another exception occurred:

Traceback (most recent call last):
  File "C:\Users\huang\LLMChat\venv\lib\site-packages\flask\app.py", line 1473, in wsgi_app
    response = self.full_dispatch_request()
  File "C:\Users\huang\LLMChat\venv\lib\site-packages\flask\app.py", line 882, in full_dispatch_request
    rv = self.handle_user_exception(e)
  File "C:\Users\huang\LLMChat\venv\lib\site-packages\flask\app.py", line 880, in full_dispatch_request
    rv = self.dispatch_request()
  File "C:\Users\huang\LLMChat\venv\lib\site-packages\flask\app.py", line 865, in dispatch_request
    return self.ensure_sync(self.view_functions[rule.endpoint])(**view_args)  # type: ignore[no-any-return]
  File "C:\Users\huang\LLMChat\main.py", line 41, in comment
    logging_config.error_logger(Exception, e)
  File "C:\Users\huang\LLMChat\logging_config.py", line 16, in error_logger
    logger.error(f'Error occurred: {e}')
AttributeError: type object 'Exception' has no attribute 'error'
2024-05-16 19:38:28,045 INFO werkzeug 127.0.0.1 - - [16/May/2024 19:38:28] "[35m[1mPOST /comment HTTP/1.1[0m" 500 -
2024-05-16 19:39:01,321 INFO werkzeug [31m[1mWARNING: This is a development server. Do not use it in a production deployment. Use a production WSGI server instead.[0m
 * Running on all addresses (0.0.0.0)
 * Running on http://127.0.0.1:5000
 * Running on http://192.168.0.176:5000
2024-05-16 19:39:01,321 INFO werkzeug [33mPress CTRL+C to quit[0m
2024-05-16 19:39:05,392 ERROR main Exception on /comment [POST]
Traceback (most recent call last):
  File "C:\Users\huang\LLMChat\main.py", line 32, in comment
    system_prompt = prompts.comment.system_prompt.format(criteria=inputs['all_criteria'],
  File "C:\Users\huang\LLMChat\venv\lib\site-packages\langchain_core\prompts\prompt.py", line 127, in format
    return DEFAULT_FORMATTER_MAPPING[self.template_format](self.template, **kwargs)
  File "C:\Users\huang\AppData\Local\Programs\Python\Python39\lib\string.py", line 161, in format
    return self.vformat(format_string, args, kwargs)
  File "C:\Users\huang\LLMChat\venv\lib\site-packages\langchain_core\utils\formatting.py", line 18, in vformat
    return super().vformat(format_string, args, kwargs)
  File "C:\Users\huang\AppData\Local\Programs\Python\Python39\lib\string.py", line 165, in vformat
    result, _ = self._vformat(format_string, args, kwargs, used_args, 2)
  File "C:\Users\huang\AppData\Local\Programs\Python\Python39\lib\string.py", line 205, in _vformat
    obj, arg_used = self.get_field(field_name, args, kwargs)
  File "C:\Users\huang\AppData\Local\Programs\Python\Python39\lib\string.py", line 270, in get_field
    obj = self.get_value(first, args, kwargs)
  File "C:\Users\huang\AppData\Local\Programs\Python\Python39\lib\string.py", line 227, in get_value
    return kwargs[key]
KeyError: 'assignment context'

During handling of the above exception, another exception occurred:

Traceback (most recent call last):
  File "C:\Users\huang\LLMChat\venv\lib\site-packages\flask\app.py", line 1473, in wsgi_app
    response = self.full_dispatch_request()
  File "C:\Users\huang\LLMChat\venv\lib\site-packages\flask\app.py", line 882, in full_dispatch_request
    rv = self.handle_user_exception(e)
  File "C:\Users\huang\LLMChat\venv\lib\site-packages\flask\app.py", line 880, in full_dispatch_request
    rv = self.dispatch_request()
  File "C:\Users\huang\LLMChat\venv\lib\site-packages\flask\app.py", line 865, in dispatch_request
    return self.ensure_sync(self.view_functions[rule.endpoint])(**view_args)  # type: ignore[no-any-return]
  File "C:\Users\huang\LLMChat\main.py", line 42, in comment
    logging_config.error_logger(Exception, e)
  File "C:\Users\huang\LLMChat\logging_config.py", line 16, in error_logger
    logger.error(f'Error occurred: {e}')
AttributeError: type object 'Exception' has no attribute 'error'
2024-05-16 19:39:05,394 INFO werkzeug 127.0.0.1 - - [16/May/2024 19:39:05] "[35m[1mPOST /comment HTTP/1.1[0m" 500 -
2024-05-16 19:50:44,534 INFO werkzeug [31m[1mWARNING: This is a development server. Do not use it in a production deployment. Use a production WSGI server instead.[0m
 * Running on all addresses (0.0.0.0)
 * Running on http://127.0.0.1:5000
 * Running on http://192.168.0.176:5000
2024-05-16 19:50:44,535 INFO werkzeug [33mPress CTRL+C to quit[0m
2024-05-16 19:51:11,353 INFO werkzeug 127.0.0.1 - - [16/May/2024 19:51:11] "POST /comment HTTP/1.1" 200 -
2024-05-16 19:53:58,775 INFO werkzeug 127.0.0.1 - - [16/May/2024 19:53:58] "POST /comment HTTP/1.1" 200 -
2024-05-16 19:54:36,627 INFO werkzeug [31m[1mWARNING: This is a development server. Do not use it in a production deployment. Use a production WSGI server instead.[0m
 * Running on all addresses (0.0.0.0)
 * Running on http://127.0.0.1:5000
 * Running on http://192.168.0.176:5000
2024-05-16 19:54:36,627 INFO werkzeug [33mPress CTRL+C to quit[0m
2024-05-16 19:54:48,970 ERROR main Exception on /comment [POST]
Traceback (most recent call last):
  File "C:\Users\huang\LLMChat\venv\lib\site-packages\flask\app.py", line 1473, in wsgi_app
    response = self.full_dispatch_request()
  File "C:\Users\huang\LLMChat\venv\lib\site-packages\flask\app.py", line 883, in full_dispatch_request
    return self.finalize_request(rv)
  File "C:\Users\huang\LLMChat\venv\lib\site-packages\flask\app.py", line 902, in finalize_request
    response = self.make_response(rv)
  File "C:\Users\huang\LLMChat\venv\lib\site-packages\flask\app.py", line 1174, in make_response
    raise TypeError(
TypeError: The view function for 'comment' did not return a valid response. The function either returned None or ended without a return statement.
2024-05-16 19:54:48,971 INFO werkzeug 127.0.0.1 - - [16/May/2024 19:54:48] "[35m[1mPOST /comment HTTP/1.1[0m" 500 -
2024-05-16 19:55:50,707 ERROR main Exception on /comment [POST]
Traceback (most recent call last):
  File "C:\Users\huang\LLMChat\venv\lib\site-packages\flask\app.py", line 1473, in wsgi_app
    response = self.full_dispatch_request()
  File "C:\Users\huang\LLMChat\venv\lib\site-packages\flask\app.py", line 883, in full_dispatch_request
    return self.finalize_request(rv)
  File "C:\Users\huang\LLMChat\venv\lib\site-packages\flask\app.py", line 902, in finalize_request
    response = self.make_response(rv)
  File "C:\Users\huang\LLMChat\venv\lib\site-packages\flask\app.py", line 1174, in make_response
    raise TypeError(
TypeError: The view function for 'comment' did not return a valid response. The function either returned None or ended without a return statement.
2024-05-16 19:55:50,707 INFO werkzeug 127.0.0.1 - - [16/May/2024 19:55:50] "[35m[1mPOST /comment HTTP/1.1[0m" 500 -
2024-05-16 20:01:26,032 INFO werkzeug [31m[1mWARNING: This is a development server. Do not use it in a production deployment. Use a production WSGI server instead.[0m
 * Running on all addresses (0.0.0.0)
 * Running on http://127.0.0.1:5000
 * Running on http://192.168.0.176:5000
2024-05-16 20:01:26,032 INFO werkzeug [33mPress CTRL+C to quit[0m
2024-05-16 20:01:31,752 ERROR main Exception on /comment [POST]
Traceback (most recent call last):
  File "C:\Users\huang\LLMChat\main.py", line 37, in comment
    response = chat.invoke(system_prompt, user_prompt, output_format=str)
  File "C:\Users\huang\LLMChat\models.py", line 39, in invoke
    raise ValueError(f"Unsupported output format:{output_format}")
ValueError: Unsupported output format:<class 'str'>

During handling of the above exception, another exception occurred:

Traceback (most recent call last):
  File "C:\Users\huang\LLMChat\venv\lib\site-packages\flask\app.py", line 1473, in wsgi_app
    response = self.full_dispatch_request()
  File "C:\Users\huang\LLMChat\venv\lib\site-packages\flask\app.py", line 882, in full_dispatch_request
    rv = self.handle_user_exception(e)
  File "C:\Users\huang\LLMChat\venv\lib\site-packages\flask\app.py", line 880, in full_dispatch_request
    rv = self.dispatch_request()
  File "C:\Users\huang\LLMChat\venv\lib\site-packages\flask\app.py", line 865, in dispatch_request
    return self.ensure_sync(self.view_functions[rule.endpoint])(**view_args)  # type: ignore[no-any-return]
  File "C:\Users\huang\LLMChat\main.py", line 42, in comment
    logging_config.error_logger(Exception, e)
  File "C:\Users\huang\LLMChat\logging_config.py", line 16, in error_logger
    logger.error(f'Error occurred: {e}')
AttributeError: type object 'Exception' has no attribute 'error'
2024-05-16 20:01:31,753 INFO werkzeug 127.0.0.1 - - [16/May/2024 20:01:31] "[35m[1mPOST /comment HTTP/1.1[0m" 500 -
2024-05-16 20:01:41,630 ERROR main Exception on /comment [POST]
Traceback (most recent call last):
  File "C:\Users\huang\LLMChat\main.py", line 37, in comment
    response = chat.invoke(system_prompt, user_prompt, output_format=str)
  File "C:\Users\huang\LLMChat\models.py", line 39, in invoke
    raise ValueError(f"Unsupported output format:{output_format}")
ValueError: Unsupported output format:<class 'str'>

During handling of the above exception, another exception occurred:

Traceback (most recent call last):
  File "C:\Users\huang\LLMChat\venv\lib\site-packages\flask\app.py", line 1473, in wsgi_app
    response = self.full_dispatch_request()
  File "C:\Users\huang\LLMChat\venv\lib\site-packages\flask\app.py", line 882, in full_dispatch_request
    rv = self.handle_user_exception(e)
  File "C:\Users\huang\LLMChat\venv\lib\site-packages\flask\app.py", line 880, in full_dispatch_request
    rv = self.dispatch_request()
  File "C:\Users\huang\LLMChat\venv\lib\site-packages\flask\app.py", line 865, in dispatch_request
    return self.ensure_sync(self.view_functions[rule.endpoint])(**view_args)  # type: ignore[no-any-return]
  File "C:\Users\huang\LLMChat\main.py", line 42, in comment
    logging_config.error_logger(Exception, e)
  File "C:\Users\huang\LLMChat\logging_config.py", line 16, in error_logger
    logger.error(f'Error occurred: {e}')
AttributeError: type object 'Exception' has no attribute 'error'
2024-05-16 20:01:41,631 INFO werkzeug 127.0.0.1 - - [16/May/2024 20:01:41] "[35m[1mPOST /comment HTTP/1.1[0m" 500 -
2024-05-16 20:02:54,991 INFO werkzeug [31m[1mWARNING: This is a development server. Do not use it in a production deployment. Use a production WSGI server instead.[0m
 * Running on all addresses (0.0.0.0)
 * Running on http://127.0.0.1:5000
 * Running on http://192.168.0.176:5000
2024-05-16 20:02:54,991 INFO werkzeug [33mPress CTRL+C to quit[0m
2024-05-16 20:03:00,104 ERROR main Exception on /comment [POST]
Traceback (most recent call last):
  File "C:\Users\huang\LLMChat\venv\lib\site-packages\flask\app.py", line 1473, in wsgi_app
    response = self.full_dispatch_request()
  File "C:\Users\huang\LLMChat\venv\lib\site-packages\flask\app.py", line 883, in full_dispatch_request
    return self.finalize_request(rv)
  File "C:\Users\huang\LLMChat\venv\lib\site-packages\flask\app.py", line 902, in finalize_request
    response = self.make_response(rv)
  File "C:\Users\huang\LLMChat\venv\lib\site-packages\flask\app.py", line 1174, in make_response
    raise TypeError(
TypeError: The view function for 'comment' did not return a valid response. The function either returned None or ended without a return statement.
2024-05-16 20:03:00,105 INFO werkzeug 127.0.0.1 - - [16/May/2024 20:03:00] "[35m[1mPOST /comment HTTP/1.1[0m" 500 -
2024-05-16 20:05:52,357 INFO werkzeug [31m[1mWARNING: This is a development server. Do not use it in a production deployment. Use a production WSGI server instead.[0m
 * Running on all addresses (0.0.0.0)
 * Running on http://127.0.0.1:5000
 * Running on http://192.168.0.176:5000
2024-05-16 20:05:52,357 INFO werkzeug [33mPress CTRL+C to quit[0m
2024-05-16 20:05:57,086 ERROR main Exception on /comment [POST]
Traceback (most recent call last):
  File "C:\Users\huang\LLMChat\main.py", line 37, in comment
    response = chat.invoke(system_prompt, user_prompt, output_format=str)
  File "C:\Users\huang\LLMChat\models.py", line 39, in invoke
    raise ValueError(f"Unsupported output format:{output_format}")
ValueError: Unsupported output format:<class 'str'>

During handling of the above exception, another exception occurred:

Traceback (most recent call last):
  File "C:\Users\huang\LLMChat\venv\lib\site-packages\flask\app.py", line 1473, in wsgi_app
    response = self.full_dispatch_request()
  File "C:\Users\huang\LLMChat\venv\lib\site-packages\flask\app.py", line 882, in full_dispatch_request
    rv = self.handle_user_exception(e)
  File "C:\Users\huang\LLMChat\venv\lib\site-packages\flask\app.py", line 880, in full_dispatch_request
    rv = self.dispatch_request()
  File "C:\Users\huang\LLMChat\venv\lib\site-packages\flask\app.py", line 865, in dispatch_request
    return self.ensure_sync(self.view_functions[rule.endpoint])(**view_args)  # type: ignore[no-any-return]
  File "C:\Users\huang\LLMChat\main.py", line 43, in comment
    logging_config.error_logger(Exception, e)
  File "C:\Users\huang\LLMChat\logging_config.py", line 16, in error_logger
    logger.error(f'Error occurred: {e}')
AttributeError: type object 'Exception' has no attribute 'error'
2024-05-16 20:05:57,087 INFO werkzeug 127.0.0.1 - - [16/May/2024 20:05:57] "[35m[1mPOST /comment HTTP/1.1[0m" 500 -
2024-05-16 20:07:27,727 INFO werkzeug [31m[1mWARNING: This is a development server. Do not use it in a production deployment. Use a production WSGI server instead.[0m
 * Running on all addresses (0.0.0.0)
 * Running on http://127.0.0.1:5000
 * Running on http://192.168.0.176:5000
2024-05-16 20:07:27,727 INFO werkzeug [33mPress CTRL+C to quit[0m
2024-05-16 20:07:40,710 ERROR main Exception on /comment [POST]
Traceback (most recent call last):
  File "C:\Users\huang\LLMChat\main.py", line 37, in comment
    response = chat.invoke(system_prompt, user_prompt, output_format=str)
  File "C:\Users\huang\LLMChat\models.py", line 39, in invoke
    raise ValueError(f"Unsupported output format:{output_format}")
ValueError: Unsupported output format:<class 'str'>

During handling of the above exception, another exception occurred:

Traceback (most recent call last):
  File "C:\Users\huang\LLMChat\venv\lib\site-packages\flask\app.py", line 1473, in wsgi_app
    response = self.full_dispatch_request()
  File "C:\Users\huang\LLMChat\venv\lib\site-packages\flask\app.py", line 882, in full_dispatch_request
    rv = self.handle_user_exception(e)
  File "C:\Users\huang\LLMChat\venv\lib\site-packages\flask\app.py", line 880, in full_dispatch_request
    rv = self.dispatch_request()
  File "C:\Users\huang\LLMChat\venv\lib\site-packages\flask\app.py", line 865, in dispatch_request
    return self.ensure_sync(self.view_functions[rule.endpoint])(**view_args)  # type: ignore[no-any-return]
  File "C:\Users\huang\LLMChat\main.py", line 44, in comment
    logging_config.error_logger(Exception, e)
  File "C:\Users\huang\LLMChat\logging_config.py", line 16, in error_logger
    logger.error(f'Error occurred: {e}')
AttributeError: type object 'Exception' has no attribute 'error'
2024-05-16 20:07:40,711 INFO werkzeug 127.0.0.1 - - [16/May/2024 20:07:40] "[35m[1mPOST /comment HTTP/1.1[0m" 500 -
2024-05-16 20:08:45,039 INFO werkzeug [31m[1mWARNING: This is a development server. Do not use it in a production deployment. Use a production WSGI server instead.[0m
 * Running on all addresses (0.0.0.0)
 * Running on http://127.0.0.1:5000
 * Running on http://192.168.0.176:5000
2024-05-16 20:08:45,039 INFO werkzeug [33mPress CTRL+C to quit[0m
2024-05-16 20:08:54,823 ERROR main Exception on /comment [POST]
Traceback (most recent call last):
  File "C:\Users\huang\LLMChat\main.py", line 37, in comment
    response = chat.invoke(system_prompt, user_prompt)
  File "C:\Users\huang\LLMChat\models.py", line 49, in invoke
    if question_prompt:
UnboundLocalError: local variable 'question_prompt' referenced before assignment

During handling of the above exception, another exception occurred:

Traceback (most recent call last):
  File "C:\Users\huang\LLMChat\venv\lib\site-packages\flask\app.py", line 1473, in wsgi_app
    response = self.full_dispatch_request()
  File "C:\Users\huang\LLMChat\venv\lib\site-packages\flask\app.py", line 882, in full_dispatch_request
    rv = self.handle_user_exception(e)
  File "C:\Users\huang\LLMChat\venv\lib\site-packages\flask\app.py", line 880, in full_dispatch_request
    rv = self.dispatch_request()
  File "C:\Users\huang\LLMChat\venv\lib\site-packages\flask\app.py", line 865, in dispatch_request
    return self.ensure_sync(self.view_functions[rule.endpoint])(**view_args)  # type: ignore[no-any-return]
  File "C:\Users\huang\LLMChat\main.py", line 44, in comment
    logging_config.error_logger(Exception, e)
  File "C:\Users\huang\LLMChat\logging_config.py", line 16, in error_logger
    logger.error(f'Error occurred: {e}')
AttributeError: type object 'Exception' has no attribute 'error'
2024-05-16 20:08:54,825 INFO werkzeug 127.0.0.1 - - [16/May/2024 20:08:54] "[35m[1mPOST /comment HTTP/1.1[0m" 500 -
2024-05-16 20:14:18,443 INFO werkzeug [31m[1mWARNING: This is a development server. Do not use it in a production deployment. Use a production WSGI server instead.[0m
 * Running on all addresses (0.0.0.0)
 * Running on http://127.0.0.1:5000
 * Running on http://192.168.0.176:5000
2024-05-16 20:14:18,443 INFO werkzeug [33mPress CTRL+C to quit[0m
2024-05-16 20:14:42,650 INFO werkzeug [31m[1mWARNING: This is a development server. Do not use it in a production deployment. Use a production WSGI server instead.[0m
 * Running on all addresses (0.0.0.0)
 * Running on http://127.0.0.1:5000
 * Running on http://192.168.0.176:5000
2024-05-16 20:14:42,650 INFO werkzeug [33mPress CTRL+C to quit[0m
2024-05-16 20:14:46,218 ERROR main Exception on /comment [POST]
Traceback (most recent call last):
  File "C:\Users\huang\LLMChat\main.py", line 42, in comment
    response = chat.invoke(system_message, user_message, output_format=str)
  File "C:\Users\huang\LLMChat\models.py", line 39, in invoke
    raise ValueError(f"Unsupported output format:{output_format}")
ValueError: Unsupported output format:<class 'str'>

During handling of the above exception, another exception occurred:

Traceback (most recent call last):
  File "C:\Users\huang\LLMChat\venv\lib\site-packages\flask\app.py", line 1473, in wsgi_app
    response = self.full_dispatch_request()
  File "C:\Users\huang\LLMChat\venv\lib\site-packages\flask\app.py", line 882, in full_dispatch_request
    rv = self.handle_user_exception(e)
  File "C:\Users\huang\LLMChat\venv\lib\site-packages\flask\app.py", line 880, in full_dispatch_request
    rv = self.dispatch_request()
  File "C:\Users\huang\LLMChat\venv\lib\site-packages\flask\app.py", line 865, in dispatch_request
    return self.ensure_sync(self.view_functions[rule.endpoint])(**view_args)  # type: ignore[no-any-return]
  File "C:\Users\huang\LLMChat\main.py", line 49, in comment
    logging_config.error_logger(Exception, e)
  File "C:\Users\huang\LLMChat\logging_config.py", line 16, in error_logger
    logger.error(f'Error occurred: {e}')
AttributeError: type object 'Exception' has no attribute 'error'
2024-05-16 20:14:46,220 INFO werkzeug 127.0.0.1 - - [16/May/2024 20:14:46] "[35m[1mPOST /comment HTTP/1.1[0m" 500 -
2024-05-16 20:16:27,564 INFO werkzeug [31m[1mWARNING: This is a development server. Do not use it in a production deployment. Use a production WSGI server instead.[0m
 * Running on all addresses (0.0.0.0)
 * Running on http://127.0.0.1:5000
 * Running on http://192.168.0.176:5000
2024-05-16 20:16:27,564 INFO werkzeug [33mPress CTRL+C to quit[0m
2024-05-16 20:16:37,188 INFO werkzeug [31m[1mWARNING: This is a development server. Do not use it in a production deployment. Use a production WSGI server instead.[0m
 * Running on all addresses (0.0.0.0)
 * Running on http://127.0.0.1:5000
 * Running on http://192.168.0.176:5000
2024-05-16 20:16:37,188 INFO werkzeug [33mPress CTRL+C to quit[0m
2024-05-16 20:17:05,009 ERROR main Exception on /comment [POST]
Traceback (most recent call last):
  File "C:\Users\huang\LLMChat\venv\lib\site-packages\flask\app.py", line 1473, in wsgi_app
    response = self.full_dispatch_request()
  File "C:\Users\huang\LLMChat\venv\lib\site-packages\flask\app.py", line 883, in full_dispatch_request
    return self.finalize_request(rv)
  File "C:\Users\huang\LLMChat\venv\lib\site-packages\flask\app.py", line 902, in finalize_request
    response = self.make_response(rv)
  File "C:\Users\huang\LLMChat\venv\lib\site-packages\flask\app.py", line 1174, in make_response
    raise TypeError(
TypeError: The view function for 'comment' did not return a valid response. The function either returned None or ended without a return statement.
2024-05-16 20:17:05,010 INFO werkzeug 127.0.0.1 - - [16/May/2024 20:17:05] "[35m[1mPOST /comment HTTP/1.1[0m" 500 -
2024-05-16 20:18:19,048 INFO werkzeug [31m[1mWARNING: This is a development server. Do not use it in a production deployment. Use a production WSGI server instead.[0m
 * Running on all addresses (0.0.0.0)
 * Running on http://127.0.0.1:5000
 * Running on http://192.168.0.176:5000
2024-05-16 20:18:19,048 INFO werkzeug [33mPress CTRL+C to quit[0m
2024-05-16 20:18:27,635 INFO werkzeug [31m[1mWARNING: This is a development server. Do not use it in a production deployment. Use a production WSGI server instead.[0m
 * Running on all addresses (0.0.0.0)
 * Running on http://127.0.0.1:5000
 * Running on http://192.168.0.176:5000
2024-05-16 20:18:27,635 INFO werkzeug [33mPress CTRL+C to quit[0m
2024-05-16 20:18:31,727 ERROR main Exception on /comment [POST]
Traceback (most recent call last):
  File "C:\Users\huang\LLMChat\venv\lib\site-packages\flask\app.py", line 1473, in wsgi_app
    response = self.full_dispatch_request()
  File "C:\Users\huang\LLMChat\venv\lib\site-packages\flask\app.py", line 883, in full_dispatch_request
    return self.finalize_request(rv)
  File "C:\Users\huang\LLMChat\venv\lib\site-packages\flask\app.py", line 902, in finalize_request
    response = self.make_response(rv)
  File "C:\Users\huang\LLMChat\venv\lib\site-packages\flask\app.py", line 1174, in make_response
    raise TypeError(
TypeError: The view function for 'comment' did not return a valid response. The function either returned None or ended without a return statement.
2024-05-16 20:18:31,728 INFO werkzeug 127.0.0.1 - - [16/May/2024 20:18:31] "[35m[1mPOST /comment HTTP/1.1[0m" 500 -
2024-05-16 20:21:03,257 INFO werkzeug [31m[1mWARNING: This is a development server. Do not use it in a production deployment. Use a production WSGI server instead.[0m
 * Running on all addresses (0.0.0.0)
 * Running on http://127.0.0.1:5000
 * Running on http://192.168.0.176:5000
2024-05-16 20:21:03,257 INFO werkzeug [33mPress CTRL+C to quit[0m
2024-05-16 20:21:10,133 ERROR main Exception on /comment [POST]
Traceback (most recent call last):
  File "C:\Users\huang\LLMChat\main.py", line 39, in comment
    response = chat.invoke(system_message, user_message, output_format="strsdadsd")
  File "C:\Users\huang\LLMChat\models.py", line 39, in invoke
    raise ValueError(f"Unsupported output format:{output_format}")
ValueError: Unsupported output format:strsdadsd

During handling of the above exception, another exception occurred:

Traceback (most recent call last):
  File "C:\Users\huang\LLMChat\venv\lib\site-packages\flask\app.py", line 1473, in wsgi_app
    response = self.full_dispatch_request()
  File "C:\Users\huang\LLMChat\venv\lib\site-packages\flask\app.py", line 882, in full_dispatch_request
    rv = self.handle_user_exception(e)
  File "C:\Users\huang\LLMChat\venv\lib\site-packages\flask\app.py", line 880, in full_dispatch_request
    rv = self.dispatch_request()
  File "C:\Users\huang\LLMChat\venv\lib\site-packages\flask\app.py", line 865, in dispatch_request
    return self.ensure_sync(self.view_functions[rule.endpoint])(**view_args)  # type: ignore[no-any-return]
  File "C:\Users\huang\LLMChat\main.py", line 46, in comment
    logging_config.error_logger(Exception, e)
  File "C:\Users\huang\LLMChat\logging_config.py", line 16, in error_logger
    logger.error(f'Error occurred: {e}')
AttributeError: type object 'Exception' has no attribute 'error'
2024-05-16 20:21:10,134 INFO werkzeug 127.0.0.1 - - [16/May/2024 20:21:10] "[35m[1mPOST /comment HTTP/1.1[0m" 500 -
2024-05-16 20:21:15,996 ERROR main Exception on /comment [POST]
Traceback (most recent call last):
  File "C:\Users\huang\LLMChat\main.py", line 39, in comment
    response = chat.invoke(system_message, user_message, output_format="strsdadsd")
  File "C:\Users\huang\LLMChat\models.py", line 39, in invoke
    raise ValueError(f"Unsupported output format:{output_format}")
ValueError: Unsupported output format:strsdadsd

During handling of the above exception, another exception occurred:

Traceback (most recent call last):
  File "C:\Users\huang\LLMChat\venv\lib\site-packages\flask\app.py", line 1473, in wsgi_app
    response = self.full_dispatch_request()
  File "C:\Users\huang\LLMChat\venv\lib\site-packages\flask\app.py", line 882, in full_dispatch_request
    rv = self.handle_user_exception(e)
  File "C:\Users\huang\LLMChat\venv\lib\site-packages\flask\app.py", line 880, in full_dispatch_request
    rv = self.dispatch_request()
  File "C:\Users\huang\LLMChat\venv\lib\site-packages\flask\app.py", line 865, in dispatch_request
    return self.ensure_sync(self.view_functions[rule.endpoint])(**view_args)  # type: ignore[no-any-return]
  File "C:\Users\huang\LLMChat\main.py", line 46, in comment
    logging_config.error_logger(Exception, e)
  File "C:\Users\huang\LLMChat\logging_config.py", line 16, in error_logger
    logger.error(f'Error occurred: {e}')
AttributeError: type object 'Exception' has no attribute 'error'
2024-05-16 20:21:15,997 INFO werkzeug 127.0.0.1 - - [16/May/2024 20:21:15] "[35m[1mPOST /comment HTTP/1.1[0m" 500 -
2024-05-16 20:23:53,723 INFO werkzeug [31m[1mWARNING: This is a development server. Do not use it in a production deployment. Use a production WSGI server instead.[0m
 * Running on all addresses (0.0.0.0)
 * Running on http://127.0.0.1:5000
 * Running on http://192.168.0.176:5000
2024-05-16 20:23:53,725 INFO werkzeug [33mPress CTRL+C to quit[0m
2024-05-16 20:23:59,659 ERROR main Exception on /comment [POST]
Traceback (most recent call last):
  File "C:\Users\huang\LLMChat\main.py", line 39, in comment
    response = chat.invoke(system_message, user_message, output_format="str")
  File "C:\Users\huang\LLMChat\models.py", line 39, in invoke
    raise ValueError(f"Unsupported output format:{output_format}")
ValueError: Unsupported output format:strsdadsd

During handling of the above exception, another exception occurred:

Traceback (most recent call last):
  File "C:\Users\huang\LLMChat\venv\lib\site-packages\flask\app.py", line 1473, in wsgi_app
    response = self.full_dispatch_request()
  File "C:\Users\huang\LLMChat\venv\lib\site-packages\flask\app.py", line 882, in full_dispatch_request
    rv = self.handle_user_exception(e)
  File "C:\Users\huang\LLMChat\venv\lib\site-packages\flask\app.py", line 880, in full_dispatch_request
    rv = self.dispatch_request()
  File "C:\Users\huang\LLMChat\venv\lib\site-packages\flask\app.py", line 865, in dispatch_request
    return self.ensure_sync(self.view_functions[rule.endpoint])(**view_args)  # type: ignore[no-any-return]
  File "C:\Users\huang\LLMChat\main.py", line 46, in comment
    logging_config.error_logger(Exception, e)
  File "C:\Users\huang\LLMChat\logging_config.py", line 16, in error_logger
    logger.error(f'Error occurred: {e}')
AttributeError: type object 'Exception' has no attribute 'error'
2024-05-16 20:23:59,660 INFO werkzeug 127.0.0.1 - - [16/May/2024 20:23:59] "[35m[1mPOST /comment HTTP/1.1[0m" 500 -
2024-05-16 20:39:21,167 INFO werkzeug [31m[1mWARNING: This is a development server. Do not use it in a production deployment. Use a production WSGI server instead.[0m
 * Running on all addresses (0.0.0.0)
 * Running on http://127.0.0.1:5000
 * Running on http://192.168.0.176:5000
2024-05-16 20:39:21,167 INFO werkzeug [33mPress CTRL+C to quit[0m
2024-05-16 20:41:00,630 INFO werkzeug 127.0.0.1 - - [16/May/2024 20:41:00] "POST /comment HTTP/1.1" 200 -
2024-05-17 16:17:27,875 INFO werkzeug [31m[1mWARNING: This is a development server. Do not use it in a production deployment. Use a production WSGI server instead.[0m
 * Running on all addresses (0.0.0.0)
 * Running on http://127.0.0.1:5000
 * Running on http://192.168.0.176:5000
2024-05-17 16:17:27,877 INFO werkzeug [33mPress CTRL+C to quit[0m
2024-05-17 16:17:38,241 INFO werkzeug 127.0.0.1 - - [17/May/2024 16:17:38] "[33mPOST /mark HTTP/1.1[0m" 404 -
2024-05-17 16:17:51,806 ERROR main Exception on /marking [POST]
Traceback (most recent call last):
  File "C:\Users\huang\LLMChat\main.py", line 111, in marking
    response = chat.invoke(system_message, user_message, output_format=mark.parser)
  File "C:\Users\huang\LLMChat\models.py", line 46, in invoke
    result = chain.invoke(user_message)
  File "C:\Users\huang\LLMChat\venv\lib\site-packages\langchain_core\runnables\base.py", line 2499, in invoke
    input = step.invoke(
  File "C:\Users\huang\LLMChat\venv\lib\site-packages\langchain_core\prompts\base.py", line 128, in invoke
    return self._call_with_config(
  File "C:\Users\huang\LLMChat\venv\lib\site-packages\langchain_core\runnables\base.py", line 1626, in _call_with_config
    context.run(
  File "C:\Users\huang\LLMChat\venv\lib\site-packages\langchain_core\runnables\config.py", line 347, in call_func_with_variable_args
    return func(input, **kwargs)  # type: ignore[call-arg]
  File "C:\Users\huang\LLMChat\venv\lib\site-packages\langchain_core\prompts\base.py", line 111, in _format_prompt_with_error_handling
    _inner_input = self._validate_input(inner_input)
  File "C:\Users\huang\LLMChat\venv\lib\site-packages\langchain_core\prompts\base.py", line 103, in _validate_input
    raise KeyError(
KeyError: 'Input to ChatPromptTemplate is missing variables {\'"foo"\', \'"properties"\'}.  Expected: [\'"foo"\', \'"properties"\'] Received: [\'user_input\']'

During handling of the above exception, another exception occurred:

Traceback (most recent call last):
  File "C:\Users\huang\LLMChat\venv\lib\site-packages\flask\app.py", line 1473, in wsgi_app
    response = self.full_dispatch_request()
  File "C:\Users\huang\LLMChat\venv\lib\site-packages\flask\app.py", line 882, in full_dispatch_request
    rv = self.handle_user_exception(e)
  File "C:\Users\huang\LLMChat\venv\lib\site-packages\flask\app.py", line 880, in full_dispatch_request
    rv = self.dispatch_request()
  File "C:\Users\huang\LLMChat\venv\lib\site-packages\flask\app.py", line 865, in dispatch_request
    return self.ensure_sync(self.view_functions[rule.endpoint])(**view_args)  # type: ignore[no-any-return]
  File "C:\Users\huang\LLMChat\main.py", line 116, in marking
    logging_config.error_logger(Exception, e)
  File "C:\Users\huang\LLMChat\logging_config.py", line 16, in error_logger
    logger.error(f'Error occurred: {e}')
AttributeError: type object 'Exception' has no attribute 'error'
2024-05-17 16:17:51,810 INFO werkzeug 127.0.0.1 - - [17/May/2024 16:17:51] "[35m[1mPOST /marking HTTP/1.1[0m" 500 -
2024-05-17 16:18:34,325 INFO werkzeug [31m[1mWARNING: This is a development server. Do not use it in a production deployment. Use a production WSGI server instead.[0m
 * Running on all addresses (0.0.0.0)
 * Running on http://127.0.0.1:5000
 * Running on http://192.168.0.176:5000
2024-05-17 16:18:34,325 INFO werkzeug [33mPress CTRL+C to quit[0m
2024-05-17 16:18:39,004 ERROR main Exception on /marking [POST]
Traceback (most recent call last):
  File "C:\Users\huang\LLMChat\venv\lib\site-packages\flask\app.py", line 1473, in wsgi_app
    response = self.full_dispatch_request()
  File "C:\Users\huang\LLMChat\venv\lib\site-packages\flask\app.py", line 883, in full_dispatch_request
    return self.finalize_request(rv)
  File "C:\Users\huang\LLMChat\venv\lib\site-packages\flask\app.py", line 902, in finalize_request
    response = self.make_response(rv)
  File "C:\Users\huang\LLMChat\venv\lib\site-packages\flask\app.py", line 1174, in make_response
    raise TypeError(
TypeError: The view function for 'marking' did not return a valid response. The function either returned None or ended without a return statement.
2024-05-17 16:18:39,004 INFO werkzeug 127.0.0.1 - - [17/May/2024 16:18:39] "[35m[1mPOST /marking HTTP/1.1[0m" 500 -
2024-05-17 16:19:46,394 INFO werkzeug [31m[1mWARNING: This is a development server. Do not use it in a production deployment. Use a production WSGI server instead.[0m
 * Running on all addresses (0.0.0.0)
 * Running on http://127.0.0.1:5000
 * Running on http://192.168.0.176:5000
2024-05-17 16:19:46,394 INFO werkzeug [33mPress CTRL+C to quit[0m
2024-05-17 16:19:51,588 ERROR main Exception on /marking [POST]
Traceback (most recent call last):
  File "C:\Users\huang\LLMChat\venv\lib\site-packages\flask\app.py", line 1473, in wsgi_app
    response = self.full_dispatch_request()
  File "C:\Users\huang\LLMChat\venv\lib\site-packages\flask\app.py", line 883, in full_dispatch_request
    return self.finalize_request(rv)
  File "C:\Users\huang\LLMChat\venv\lib\site-packages\flask\app.py", line 902, in finalize_request
    response = self.make_response(rv)
  File "C:\Users\huang\LLMChat\venv\lib\site-packages\flask\app.py", line 1174, in make_response
    raise TypeError(
TypeError: The view function for 'marking' did not return a valid response. The function either returned None or ended without a return statement.
2024-05-17 16:19:51,589 INFO werkzeug 127.0.0.1 - - [17/May/2024 16:19:51] "[35m[1mPOST /marking HTTP/1.1[0m" 500 -
2024-05-17 16:20:56,035 INFO werkzeug [31m[1mWARNING: This is a development server. Do not use it in a production deployment. Use a production WSGI server instead.[0m
 * Running on all addresses (0.0.0.0)
 * Running on http://127.0.0.1:5000
 * Running on http://192.168.0.176:5000
2024-05-17 16:20:56,035 INFO werkzeug [33mPress CTRL+C to quit[0m
2024-05-17 16:20:58,935 ERROR main Exception on /marking [POST]
Traceback (most recent call last):
  File "C:\Users\huang\LLMChat\main.py", line 113, in marking
    response = chat.invoke(system_message, user_message, output_format=mark.parser)
  File "C:\Users\huang\LLMChat\models.py", line 46, in invoke
    result = chain.invoke(user_message)
  File "C:\Users\huang\LLMChat\venv\lib\site-packages\langchain_core\runnables\base.py", line 2499, in invoke
    input = step.invoke(
  File "C:\Users\huang\LLMChat\venv\lib\site-packages\langchain_core\prompts\base.py", line 128, in invoke
    return self._call_with_config(
  File "C:\Users\huang\LLMChat\venv\lib\site-packages\langchain_core\runnables\base.py", line 1626, in _call_with_config
    context.run(
  File "C:\Users\huang\LLMChat\venv\lib\site-packages\langchain_core\runnables\config.py", line 347, in call_func_with_variable_args
    return func(input, **kwargs)  # type: ignore[call-arg]
  File "C:\Users\huang\LLMChat\venv\lib\site-packages\langchain_core\prompts\base.py", line 111, in _format_prompt_with_error_handling
    _inner_input = self._validate_input(inner_input)
  File "C:\Users\huang\LLMChat\venv\lib\site-packages\langchain_core\prompts\base.py", line 103, in _validate_input
    raise KeyError(
KeyError: 'Input to ChatPromptTemplate is missing variables {\'"properties"\', \'"foo"\'}.  Expected: [\'"foo"\', \'"properties"\'] Received: [\'user_input\']'

During handling of the above exception, another exception occurred:

Traceback (most recent call last):
  File "C:\Users\huang\LLMChat\venv\lib\site-packages\flask\app.py", line 1473, in wsgi_app
    response = self.full_dispatch_request()
  File "C:\Users\huang\LLMChat\venv\lib\site-packages\flask\app.py", line 882, in full_dispatch_request
    rv = self.handle_user_exception(e)
  File "C:\Users\huang\LLMChat\venv\lib\site-packages\flask\app.py", line 880, in full_dispatch_request
    rv = self.dispatch_request()
  File "C:\Users\huang\LLMChat\venv\lib\site-packages\flask\app.py", line 865, in dispatch_request
    return self.ensure_sync(self.view_functions[rule.endpoint])(**view_args)  # type: ignore[no-any-return]
  File "C:\Users\huang\LLMChat\main.py", line 118, in marking
    logging_config.error_logger(Exception, e)
  File "C:\Users\huang\LLMChat\logging_config.py", line 16, in error_logger
    logger.error(f'Error occurred: {e}')
AttributeError: type object 'Exception' has no attribute 'error'
2024-05-17 16:20:58,937 INFO werkzeug 127.0.0.1 - - [17/May/2024 16:20:58] "[35m[1mPOST /marking HTTP/1.1[0m" 500 -
2024-05-17 16:21:56,716 INFO werkzeug [31m[1mWARNING: This is a development server. Do not use it in a production deployment. Use a production WSGI server instead.[0m
 * Running on all addresses (0.0.0.0)
 * Running on http://127.0.0.1:5000
 * Running on http://192.168.0.176:5000
2024-05-17 16:21:56,717 INFO werkzeug [33mPress CTRL+C to quit[0m
2024-05-17 16:22:00,193 ERROR main Exception on /marking [POST]
Traceback (most recent call last):
  File "C:\Users\huang\LLMChat\main.py", line 113, in marking
    response = chat.invoke(system_message, user_message, output_format='str')
  File "C:\Users\huang\LLMChat\models.py", line 46, in invoke
    result = chain.invoke(user_message)
  File "C:\Users\huang\LLMChat\venv\lib\site-packages\langchain_core\runnables\base.py", line 2499, in invoke
    input = step.invoke(
  File "C:\Users\huang\LLMChat\venv\lib\site-packages\langchain_core\prompts\base.py", line 128, in invoke
    return self._call_with_config(
  File "C:\Users\huang\LLMChat\venv\lib\site-packages\langchain_core\runnables\base.py", line 1626, in _call_with_config
    context.run(
  File "C:\Users\huang\LLMChat\venv\lib\site-packages\langchain_core\runnables\config.py", line 347, in call_func_with_variable_args
    return func(input, **kwargs)  # type: ignore[call-arg]
  File "C:\Users\huang\LLMChat\venv\lib\site-packages\langchain_core\prompts\base.py", line 111, in _format_prompt_with_error_handling
    _inner_input = self._validate_input(inner_input)
  File "C:\Users\huang\LLMChat\venv\lib\site-packages\langchain_core\prompts\base.py", line 103, in _validate_input
    raise KeyError(
KeyError: 'Input to ChatPromptTemplate is missing variables {\'"properties"\', \'"foo"\'}.  Expected: [\'"foo"\', \'"properties"\'] Received: [\'user_input\']'

During handling of the above exception, another exception occurred:

Traceback (most recent call last):
  File "C:\Users\huang\LLMChat\venv\lib\site-packages\flask\app.py", line 1473, in wsgi_app
    response = self.full_dispatch_request()
  File "C:\Users\huang\LLMChat\venv\lib\site-packages\flask\app.py", line 882, in full_dispatch_request
    rv = self.handle_user_exception(e)
  File "C:\Users\huang\LLMChat\venv\lib\site-packages\flask\app.py", line 880, in full_dispatch_request
    rv = self.dispatch_request()
  File "C:\Users\huang\LLMChat\venv\lib\site-packages\flask\app.py", line 865, in dispatch_request
    return self.ensure_sync(self.view_functions[rule.endpoint])(**view_args)  # type: ignore[no-any-return]
  File "C:\Users\huang\LLMChat\main.py", line 118, in marking
    logging_config.error_logger(Exception, e)
  File "C:\Users\huang\LLMChat\logging_config.py", line 16, in error_logger
    logger.error(f'Error occurred: {e}')
AttributeError: type object 'Exception' has no attribute 'error'
2024-05-17 16:22:00,195 INFO werkzeug 127.0.0.1 - - [17/May/2024 16:22:00] "[35m[1mPOST /marking HTTP/1.1[0m" 500 -
2024-05-17 19:56:23,950 INFO werkzeug [31m[1mWARNING: This is a development server. Do not use it in a production deployment. Use a production WSGI server instead.[0m
 * Running on all addresses (0.0.0.0)
 * Running on http://127.0.0.1:5000
 * Running on http://192.168.0.176:5000
2024-05-17 19:56:23,952 INFO werkzeug [33mPress CTRL+C to quit[0m
2024-05-17 19:56:50,792 INFO werkzeug 127.0.0.1 - - [17/May/2024 19:56:50] "POST /marking HTTP/1.1" 200 -
2024-05-17 19:57:39,054 ERROR main Exception on /comment [POST]
Traceback (most recent call last):
  File "C:\Users\huang\LLMChat\main.py", line 30, in comment
    system_message = comment.system_prompt.format(criteria=inputs['all_criteria'],
AttributeError: 'function' object has no attribute 'system_prompt'

During handling of the above exception, another exception occurred:

Traceback (most recent call last):
  File "C:\Users\huang\LLMChat\venv\lib\site-packages\flask\app.py", line 1473, in wsgi_app
    response = self.full_dispatch_request()
  File "C:\Users\huang\LLMChat\venv\lib\site-packages\flask\app.py", line 882, in full_dispatch_request
    rv = self.handle_user_exception(e)
  File "C:\Users\huang\LLMChat\venv\lib\site-packages\flask\app.py", line 880, in full_dispatch_request
    rv = self.dispatch_request()
  File "C:\Users\huang\LLMChat\venv\lib\site-packages\flask\app.py", line 865, in dispatch_request
    return self.ensure_sync(self.view_functions[rule.endpoint])(**view_args)  # type: ignore[no-any-return]
  File "C:\Users\huang\LLMChat\main.py", line 40, in comment
    logging_config.error_logger(Exception, e)
  File "C:\Users\huang\LLMChat\logging_config.py", line 16, in error_logger
    logger.error(f'Error occurred: {e}')
AttributeError: type object 'Exception' has no attribute 'error'
2024-05-17 19:57:39,055 INFO werkzeug 127.0.0.1 - - [17/May/2024 19:57:39] "[35m[1mPOST /comment HTTP/1.1[0m" 500 -
2024-05-17 19:59:21,129 INFO werkzeug [31m[1mWARNING: This is a development server. Do not use it in a production deployment. Use a production WSGI server instead.[0m
 * Running on all addresses (0.0.0.0)
 * Running on http://127.0.0.1:5000
 * Running on http://192.168.0.176:5000
2024-05-17 19:59:21,129 INFO werkzeug [33mPress CTRL+C to quit[0m
2024-05-17 19:59:24,446 ERROR main Exception on /comment [POST]
Traceback (most recent call last):
  File "C:\Users\huang\LLMChat\main.py", line 30, in comment
    system_message = comment.system_prompt.format(criteria=inputs['all_criteria'],
AttributeError: 'function' object has no attribute 'system_prompt'

During handling of the above exception, another exception occurred:

Traceback (most recent call last):
  File "C:\Users\huang\LLMChat\venv\lib\site-packages\flask\app.py", line 1473, in wsgi_app
    response = self.full_dispatch_request()
  File "C:\Users\huang\LLMChat\venv\lib\site-packages\flask\app.py", line 882, in full_dispatch_request
    rv = self.handle_user_exception(e)
  File "C:\Users\huang\LLMChat\venv\lib\site-packages\flask\app.py", line 880, in full_dispatch_request
    rv = self.dispatch_request()
  File "C:\Users\huang\LLMChat\venv\lib\site-packages\flask\app.py", line 865, in dispatch_request
    return self.ensure_sync(self.view_functions[rule.endpoint])(**view_args)  # type: ignore[no-any-return]
  File "C:\Users\huang\LLMChat\main.py", line 40, in comment
    logging_config.error_logger(Exception, e)
  File "C:\Users\huang\LLMChat\logging_config.py", line 16, in error_logger
    logger.error(f'Error occurred: {e}')
AttributeError: type object 'Exception' has no attribute 'error'
2024-05-17 19:59:24,447 INFO werkzeug 127.0.0.1 - - [17/May/2024 19:59:24] "[35m[1mPOST /comment HTTP/1.1[0m" 500 -
2024-05-17 19:59:26,656 ERROR main Exception on /comment [POST]
Traceback (most recent call last):
  File "C:\Users\huang\LLMChat\main.py", line 30, in comment
    system_message = comment.system_prompt.format(criteria=inputs['all_criteria'],
AttributeError: 'function' object has no attribute 'system_prompt'

During handling of the above exception, another exception occurred:

Traceback (most recent call last):
  File "C:\Users\huang\LLMChat\venv\lib\site-packages\flask\app.py", line 1473, in wsgi_app
    response = self.full_dispatch_request()
  File "C:\Users\huang\LLMChat\venv\lib\site-packages\flask\app.py", line 882, in full_dispatch_request
    rv = self.handle_user_exception(e)
  File "C:\Users\huang\LLMChat\venv\lib\site-packages\flask\app.py", line 880, in full_dispatch_request
    rv = self.dispatch_request()
  File "C:\Users\huang\LLMChat\venv\lib\site-packages\flask\app.py", line 865, in dispatch_request
    return self.ensure_sync(self.view_functions[rule.endpoint])(**view_args)  # type: ignore[no-any-return]
  File "C:\Users\huang\LLMChat\main.py", line 40, in comment
    logging_config.error_logger(Exception, e)
  File "C:\Users\huang\LLMChat\logging_config.py", line 16, in error_logger
    logger.error(f'Error occurred: {e}')
AttributeError: type object 'Exception' has no attribute 'error'
2024-05-17 19:59:26,657 INFO werkzeug 127.0.0.1 - - [17/May/2024 19:59:26] "[35m[1mPOST /comment HTTP/1.1[0m" 500 -
2024-05-17 20:32:25,641 INFO werkzeug [31m[1mWARNING: This is a development server. Do not use it in a production deployment. Use a production WSGI server instead.[0m
 * Running on all addresses (0.0.0.0)
 * Running on http://127.0.0.1:5000
 * Running on http://192.168.0.176:5000
2024-05-17 20:32:25,643 INFO werkzeug [33mPress CTRL+C to quit[0m
2024-05-17 20:32:37,894 ERROR main Exception on /grade [POST]
Traceback (most recent call last):
  File "C:\Users\huang\LLMChat\main.py", line 48, in grade
    system_message = grade.system_prompt.format(criteria=inputs['criteria'],
AttributeError: 'function' object has no attribute 'system_prompt'

During handling of the above exception, another exception occurred:

Traceback (most recent call last):
  File "C:\Users\huang\LLMChat\venv\lib\site-packages\flask\app.py", line 1473, in wsgi_app
    response = self.full_dispatch_request()
  File "C:\Users\huang\LLMChat\venv\lib\site-packages\flask\app.py", line 882, in full_dispatch_request
    rv = self.handle_user_exception(e)
  File "C:\Users\huang\LLMChat\venv\lib\site-packages\flask\app.py", line 880, in full_dispatch_request
    rv = self.dispatch_request()
  File "C:\Users\huang\LLMChat\venv\lib\site-packages\flask\app.py", line 865, in dispatch_request
    return self.ensure_sync(self.view_functions[rule.endpoint])(**view_args)  # type: ignore[no-any-return]
  File "C:\Users\huang\LLMChat\main.py", line 57, in grade
    logging_config.error_logger(Exception, e)
  File "C:\Users\huang\LLMChat\logging_config.py", line 16, in error_logger
    logger.error(f'Error occurred: {e}')
AttributeError: type object 'Exception' has no attribute 'error'
2024-05-17 20:32:37,896 INFO werkzeug 127.0.0.1 - - [17/May/2024 20:32:37] "[35m[1mPOST /grade HTTP/1.1[0m" 500 -
2024-05-17 20:33:41,935 ERROR main Exception on /grade [POST]
Traceback (most recent call last):
  File "C:\Users\huang\LLMChat\main.py", line 48, in grade
    system_message = grade.system_prompt.format(criteria=inputs['criteria'],
AttributeError: 'function' object has no attribute 'system_prompt'

During handling of the above exception, another exception occurred:

Traceback (most recent call last):
  File "C:\Users\huang\LLMChat\venv\lib\site-packages\flask\app.py", line 1473, in wsgi_app
    response = self.full_dispatch_request()
  File "C:\Users\huang\LLMChat\venv\lib\site-packages\flask\app.py", line 882, in full_dispatch_request
    rv = self.handle_user_exception(e)
  File "C:\Users\huang\LLMChat\venv\lib\site-packages\flask\app.py", line 880, in full_dispatch_request
    rv = self.dispatch_request()
  File "C:\Users\huang\LLMChat\venv\lib\site-packages\flask\app.py", line 865, in dispatch_request
    return self.ensure_sync(self.view_functions[rule.endpoint])(**view_args)  # type: ignore[no-any-return]
  File "C:\Users\huang\LLMChat\main.py", line 57, in grade
    logging_config.error_logger(Exception, e)
  File "C:\Users\huang\LLMChat\logging_config.py", line 16, in error_logger
    logger.error(f'Error occurred: {e}')
AttributeError: type object 'Exception' has no attribute 'error'
2024-05-17 20:33:41,935 INFO werkzeug 127.0.0.1 - - [17/May/2024 20:33:41] "[35m[1mPOST /grade HTTP/1.1[0m" 500 -
2024-05-17 20:40:27,944 ERROR main Exception on /comment [POST]
Traceback (most recent call last):
  File "C:\Users\huang\LLMChat\main.py", line 30, in comment
    system_message = comment.system_prompt.format(criteria=inputs['all_criteria'],
AttributeError: 'function' object has no attribute 'system_prompt'

During handling of the above exception, another exception occurred:

Traceback (most recent call last):
  File "C:\Users\huang\LLMChat\venv\lib\site-packages\flask\app.py", line 1473, in wsgi_app
    response = self.full_dispatch_request()
  File "C:\Users\huang\LLMChat\venv\lib\site-packages\flask\app.py", line 882, in full_dispatch_request
    rv = self.handle_user_exception(e)
  File "C:\Users\huang\LLMChat\venv\lib\site-packages\flask\app.py", line 880, in full_dispatch_request
    rv = self.dispatch_request()
  File "C:\Users\huang\LLMChat\venv\lib\site-packages\flask\app.py", line 865, in dispatch_request
    return self.ensure_sync(self.view_functions[rule.endpoint])(**view_args)  # type: ignore[no-any-return]
  File "C:\Users\huang\LLMChat\main.py", line 40, in comment
    logging_config.error_logger(Exception, e)
  File "C:\Users\huang\LLMChat\logging_config.py", line 16, in error_logger
    logger.error(f'Error occurred: {e}')
AttributeError: type object 'Exception' has no attribute 'error'
2024-05-17 20:40:27,945 INFO werkzeug 127.0.0.1 - - [17/May/2024 20:40:27] "[35m[1mPOST /comment HTTP/1.1[0m" 500 -
2024-05-17 20:53:41,057 INFO werkzeug [31m[1mWARNING: This is a development server. Do not use it in a production deployment. Use a production WSGI server instead.[0m
 * Running on all addresses (0.0.0.0)
 * Running on http://127.0.0.1:5000
 * Running on http://192.168.0.176:5000
2024-05-17 20:53:41,058 INFO werkzeug [33mPress CTRL+C to quit[0m
2024-05-17 20:53:44,249 ERROR main Exception on /comment [POST]
Traceback (most recent call last):
  File "C:\Users\huang\LLMChat\main.py", line 30, in comment
    system_message = comment.system_prompt.format(criteria=inputs['all_criteria'],
AttributeError: 'function' object has no attribute 'system_prompt'

During handling of the above exception, another exception occurred:

Traceback (most recent call last):
  File "C:\Users\huang\LLMChat\venv\lib\site-packages\flask\app.py", line 1473, in wsgi_app
    response = self.full_dispatch_request()
  File "C:\Users\huang\LLMChat\venv\lib\site-packages\flask\app.py", line 882, in full_dispatch_request
    rv = self.handle_user_exception(e)
  File "C:\Users\huang\LLMChat\venv\lib\site-packages\flask\app.py", line 880, in full_dispatch_request
    rv = self.dispatch_request()
  File "C:\Users\huang\LLMChat\venv\lib\site-packages\flask\app.py", line 865, in dispatch_request
    return self.ensure_sync(self.view_functions[rule.endpoint])(**view_args)  # type: ignore[no-any-return]
  File "C:\Users\huang\LLMChat\main.py", line 40, in comment
    logging_config.error_logger(Exception, e)
  File "C:\Users\huang\LLMChat\logging_config.py", line 16, in error_logger
    logger.error(f'Error occurred: {e}')
AttributeError: type object 'Exception' has no attribute 'error'
2024-05-17 20:53:44,251 INFO werkzeug 127.0.0.1 - - [17/May/2024 20:53:44] "[35m[1mPOST /comment HTTP/1.1[0m" 500 -
2024-05-17 20:53:46,389 ERROR main Exception on /comment [POST]
Traceback (most recent call last):
  File "C:\Users\huang\LLMChat\main.py", line 30, in comment
    system_message = comment.system_prompt.format(criteria=inputs['all_criteria'],
AttributeError: 'function' object has no attribute 'system_prompt'

During handling of the above exception, another exception occurred:

Traceback (most recent call last):
  File "C:\Users\huang\LLMChat\venv\lib\site-packages\flask\app.py", line 1473, in wsgi_app
    response = self.full_dispatch_request()
  File "C:\Users\huang\LLMChat\venv\lib\site-packages\flask\app.py", line 882, in full_dispatch_request
    rv = self.handle_user_exception(e)
  File "C:\Users\huang\LLMChat\venv\lib\site-packages\flask\app.py", line 880, in full_dispatch_request
    rv = self.dispatch_request()
  File "C:\Users\huang\LLMChat\venv\lib\site-packages\flask\app.py", line 865, in dispatch_request
    return self.ensure_sync(self.view_functions[rule.endpoint])(**view_args)  # type: ignore[no-any-return]
  File "C:\Users\huang\LLMChat\main.py", line 40, in comment
    logging_config.error_logger(Exception, e)
  File "C:\Users\huang\LLMChat\logging_config.py", line 16, in error_logger
    logger.error(f'Error occurred: {e}')
AttributeError: type object 'Exception' has no attribute 'error'
2024-05-17 20:53:46,390 INFO werkzeug 127.0.0.1 - - [17/May/2024 20:53:46] "[35m[1mPOST /comment HTTP/1.1[0m" 500 -
2024-05-17 20:53:47,694 ERROR main Exception on /comment [POST]
Traceback (most recent call last):
  File "C:\Users\huang\LLMChat\main.py", line 30, in comment
    system_message = comment.system_prompt.format(criteria=inputs['all_criteria'],
AttributeError: 'function' object has no attribute 'system_prompt'

During handling of the above exception, another exception occurred:

Traceback (most recent call last):
  File "C:\Users\huang\LLMChat\venv\lib\site-packages\flask\app.py", line 1473, in wsgi_app
    response = self.full_dispatch_request()
  File "C:\Users\huang\LLMChat\venv\lib\site-packages\flask\app.py", line 882, in full_dispatch_request
    rv = self.handle_user_exception(e)
  File "C:\Users\huang\LLMChat\venv\lib\site-packages\flask\app.py", line 880, in full_dispatch_request
    rv = self.dispatch_request()
  File "C:\Users\huang\LLMChat\venv\lib\site-packages\flask\app.py", line 865, in dispatch_request
    return self.ensure_sync(self.view_functions[rule.endpoint])(**view_args)  # type: ignore[no-any-return]
  File "C:\Users\huang\LLMChat\main.py", line 40, in comment
    logging_config.error_logger(Exception, e)
  File "C:\Users\huang\LLMChat\logging_config.py", line 16, in error_logger
    logger.error(f'Error occurred: {e}')
AttributeError: type object 'Exception' has no attribute 'error'
2024-05-17 20:53:47,695 INFO werkzeug 127.0.0.1 - - [17/May/2024 20:53:47] "[35m[1mPOST /comment HTTP/1.1[0m" 500 -
2024-05-17 20:53:48,693 ERROR main Exception on /comment [POST]
Traceback (most recent call last):
  File "C:\Users\huang\LLMChat\main.py", line 30, in comment
    system_message = comment.system_prompt.format(criteria=inputs['all_criteria'],
AttributeError: 'function' object has no attribute 'system_prompt'

During handling of the above exception, another exception occurred:

Traceback (most recent call last):
  File "C:\Users\huang\LLMChat\venv\lib\site-packages\flask\app.py", line 1473, in wsgi_app
    response = self.full_dispatch_request()
  File "C:\Users\huang\LLMChat\venv\lib\site-packages\flask\app.py", line 882, in full_dispatch_request
    rv = self.handle_user_exception(e)
  File "C:\Users\huang\LLMChat\venv\lib\site-packages\flask\app.py", line 880, in full_dispatch_request
    rv = self.dispatch_request()
  File "C:\Users\huang\LLMChat\venv\lib\site-packages\flask\app.py", line 865, in dispatch_request
    return self.ensure_sync(self.view_functions[rule.endpoint])(**view_args)  # type: ignore[no-any-return]
  File "C:\Users\huang\LLMChat\main.py", line 40, in comment
    logging_config.error_logger(Exception, e)
  File "C:\Users\huang\LLMChat\logging_config.py", line 16, in error_logger
    logger.error(f'Error occurred: {e}')
AttributeError: type object 'Exception' has no attribute 'error'
2024-05-17 20:53:48,694 INFO werkzeug 127.0.0.1 - - [17/May/2024 20:53:48] "[35m[1mPOST /comment HTTP/1.1[0m" 500 -
2024-05-17 20:54:58,235 ERROR main Exception on /comment [POST]
Traceback (most recent call last):
  File "C:\Users\huang\LLMChat\main.py", line 30, in comment
    system_message = comment.system_prompt.format(criteria=inputs['all_criteria'],
AttributeError: 'function' object has no attribute 'system_prompt'

During handling of the above exception, another exception occurred:

Traceback (most recent call last):
  File "C:\Users\huang\LLMChat\venv\lib\site-packages\flask\app.py", line 1473, in wsgi_app
    response = self.full_dispatch_request()
  File "C:\Users\huang\LLMChat\venv\lib\site-packages\flask\app.py", line 882, in full_dispatch_request
    rv = self.handle_user_exception(e)
  File "C:\Users\huang\LLMChat\venv\lib\site-packages\flask\app.py", line 880, in full_dispatch_request
    rv = self.dispatch_request()
  File "C:\Users\huang\LLMChat\venv\lib\site-packages\flask\app.py", line 865, in dispatch_request
    return self.ensure_sync(self.view_functions[rule.endpoint])(**view_args)  # type: ignore[no-any-return]
  File "C:\Users\huang\LLMChat\main.py", line 40, in comment
    logging_config.error_logger(Exception, e)
  File "C:\Users\huang\LLMChat\logging_config.py", line 16, in error_logger
    logger.error(f'Error occurred: {e}')
AttributeError: type object 'Exception' has no attribute 'error'
2024-05-17 20:54:58,236 INFO werkzeug 127.0.0.1 - - [17/May/2024 20:54:58] "[35m[1mPOST /comment HTTP/1.1[0m" 500 -
2024-05-17 20:57:01,215 INFO werkzeug [31m[1mWARNING: This is a development server. Do not use it in a production deployment. Use a production WSGI server instead.[0m
 * Running on all addresses (0.0.0.0)
 * Running on http://127.0.0.1:5000
 * Running on http://192.168.0.176:5000
2024-05-17 20:57:01,215 INFO werkzeug [33mPress CTRL+C to quit[0m
2024-05-17 20:57:20,867 INFO werkzeug [31m[1mWARNING: This is a development server. Do not use it in a production deployment. Use a production WSGI server instead.[0m
 * Running on all addresses (0.0.0.0)
 * Running on http://127.0.0.1:5000
 * Running on http://192.168.0.176:5000
2024-05-17 20:57:20,867 INFO werkzeug [33mPress CTRL+C to quit[0m
2024-05-17 20:57:20,873 INFO werkzeug  * Restarting with stat
2024-05-17 20:57:23,731 WARNING werkzeug  * Debugger is active!
2024-05-17 20:57:23,735 INFO werkzeug  * Debugger PIN: 498-484-118
2024-05-17 20:57:47,394 INFO werkzeug 127.0.0.1 - - [17/May/2024 20:57:47] "[35m[1mPOST /comment HTTP/1.1[0m" 500 -
2024-05-17 20:59:50,963 INFO werkzeug  * Detected change in 'C:\\Users\\huang\\LLMChat\\main.py', reloading
2024-05-17 20:59:51,019 INFO werkzeug  * Restarting with stat
2024-05-17 20:59:54,181 WARNING werkzeug  * Debugger is active!
2024-05-17 20:59:54,194 INFO werkzeug  * Debugger PIN: 498-484-118
2024-05-17 20:59:58,773 INFO werkzeug 127.0.0.1 - - [17/May/2024 20:59:58] "[35m[1mPOST /comment HTTP/1.1[0m" 500 -
2024-05-17 21:03:06,301 INFO werkzeug [31m[1mWARNING: This is a development server. Do not use it in a production deployment. Use a production WSGI server instead.[0m
 * Running on all addresses (0.0.0.0)
 * Running on http://127.0.0.1:5000
 * Running on http://192.168.0.176:5000
2024-05-17 21:03:06,301 INFO werkzeug [33mPress CTRL+C to quit[0m
2024-05-17 21:03:06,301 INFO werkzeug  * Restarting with stat
2024-05-17 21:03:09,207 WARNING werkzeug  * Debugger is active!
2024-05-17 21:03:09,211 INFO werkzeug  * Debugger PIN: 498-484-118
2024-05-17 21:04:54,303 INFO werkzeug 127.0.0.1 - - [17/May/2024 21:04:54] "POST /comment HTTP/1.1" 200 -
2024-05-17 21:05:35,114 INFO werkzeug  * Detected change in 'C:\\Users\\huang\\LLMChat\\main.py', reloading
2024-05-17 21:05:35,167 INFO werkzeug  * Restarting with stat
2024-05-17 21:05:38,108 WARNING werkzeug  * Debugger is active!
2024-05-17 21:05:38,112 INFO werkzeug  * Debugger PIN: 498-484-118
2024-05-17 21:05:45,504 INFO werkzeug [31m[1mWARNING: This is a development server. Do not use it in a production deployment. Use a production WSGI server instead.[0m
 * Running on all addresses (0.0.0.0)
 * Running on http://127.0.0.1:5000
 * Running on http://192.168.0.176:5000
2024-05-17 21:05:45,505 INFO werkzeug [33mPress CTRL+C to quit[0m
2024-05-17 21:05:45,505 INFO werkzeug  * Restarting with stat
2024-05-17 21:05:48,425 WARNING werkzeug  * Debugger is active!
2024-05-17 21:05:48,429 INFO werkzeug  * Debugger PIN: 498-484-118
2024-05-17 21:06:53,796 INFO werkzeug 127.0.0.1 - - [17/May/2024 21:06:53] "POST /grade HTTP/1.1" 200 -
2024-05-17 21:19:43,168 INFO werkzeug [31m[1mWARNING: This is a development server. Do not use it in a production deployment. Use a production WSGI server instead.[0m
 * Running on all addresses (0.0.0.0)
 * Running on http://127.0.0.1:5000
 * Running on http://192.168.0.176:5000
2024-05-17 21:19:43,168 INFO werkzeug [33mPress CTRL+C to quit[0m
2024-05-17 21:19:43,169 INFO werkzeug  * Restarting with stat
2024-05-17 21:19:46,139 WARNING werkzeug  * Debugger is active!
2024-05-17 21:19:46,151 INFO werkzeug  * Debugger PIN: 498-484-118
2024-05-17 21:21:20,150 INFO werkzeug 127.0.0.1 - - [17/May/2024 21:21:20] "POST /grade HTTP/1.1" 200 -
2024-05-17 21:22:25,499 INFO werkzeug  * Detected change in 'C:\\Users\\huang\\LLMChat\\test_mark.py', reloading
2024-05-17 21:22:25,558 INFO werkzeug  * Restarting with stat
